Workbook

Sheet Balises
A1: Région | B1: Département | C1: Dépt | D1: N° | E1: Balise | F1: Réseau | G1: Statut | H1: Alt. balise (m) | I1: Lien balise | J1: Lat | K1: Lon | L1: Spot le plus proche (<5 km) | M1: Dist. (km) | N1: Vent idéal | O1: Vent possible | P1: Alt. déco (m) | Q1: Alt. atterro (m) | R1: D+ (m) | S1: Atterrissage | T1: Therm. | U1: Soar. | V1: Treuil | W1: Règles / restrictions | X1: Météo & pièges | Y1: Remarques | Z1: Accès | AA1: Fiche Paragliding Earth | AB1: Note balise (club)
A2: Alsace | B2: Bas Rhin | C2: 67 | D2: 1007 | E2: Altenberg | F2: Holfuy | G2: OK | H2: 880 | I2: https://www.balisemeteo.com/balise.php?idBalise=1007 | J2: 48.2954 | K2: 7.3128 | L2: Altenberg - rocher du coucou | M2: 0.38 | N2: NE | O2: N | P2: 300 | Q2: 759 | T2: oui | U2: oui | W2: MAX ALTITUDE : 1500M_x000D_ OPEN ONLY FROM MARCH 1st TO OCTOBER 31st_x000D_ http://lavl.free.fr/paragliding-vosges.html_x000D_ http://lavl.free.fr/Espace-Aerien-Vosges.html | AA2: http://www.paraglidingearth.com/?site=2941 | AB2: Balise du site Altenberg - Rocher du Coucou Le vent d'un large secteur W n'est pas pertinent, l'anémomètre est déventé par l'antenne sur laquelle il est fixé.
A3: Alsace | B3: Bas Rhin | C3: 67 | D3: 2061 | E3: Avolsheim | F3: Openwindmap | G3: OK | H3: 167 | I3: https://www.balisemeteo.com/balise.php?idBalise=2061 | J3: 48.557077 | K3: 7.515378 | L3: aucun à <5 km
A4: Alsace | B4: Bas Rhin | C4: 67 | D4: 2560 | E4: Base ULM de Batzendorf | F4: Openwindmap | G4: OK | H4: 200 | I4: https://www.balisemeteo.com/balise.php?idBalise=2560 | J4: 48.802633 | K4: 7.727189 | L4: aucun à <5 km
A5: Alsace | B5: Bas Rhin | C5: 67 | D5: 74 | E5: Breitenbach | F5: Adison | G5: OK | H5: 948 | I5: https://www.balisemeteo.com/balise.php?idBalise=74 | J5: 48.3839 | K5: 7.28301 | L5: Breitenbach-Pelage | M5: 0.04 | N5: SE·S | O5: E·SW | P5: 934 | Q5: 436 | R5: 498 | T5: oui | Y5: Do'nt fly ower 1350m, limit of TMA!_x000D_ _x000D_ Official informations:_x000D_ http://www.grandvol.com/site.htm#Carte | AA5: http://www.paraglidingearth.com/?site=2944 | AB5: <u><b>ATTENTION :</b></u></br> </br> - Le site est proche de la CTR de Strasbourg et se trouve sous deux espaces aériens contigus : Plafonds 1350m et 1500m à respecter.</br> </br> - une <b>PTU</b> coté village est <b><u>obligatoire</u></b> en approche du terrain d'atterrissage</br> </br> - Orientations: Sud-Est et Sud-Ouest
A6: Alsace | B6: Bas Rhin | C6: 67 | D6: 5000 | E6: Eckbolsheim | F6: — | G6: OK | H6: 144 | I6: https://www.balisemeteo.com/balise.php?idBalise=5000 | J6: 48.575568 | K6: 7.686625 | L6: aucun à <5 km | AB6: Balise située à Eckbolsheim, dégagée bien au vent d'Ouest<br> Bien représentative des conditions possibles<br> Pour le site de Mundolsheim<br> (capteur à ultrtasons à 10m / sol)
A7: Alsace | B7: Bas Rhin | C7: 67 | D7: 5001 | E7: Grendelbruch | F7: — | G7: En maintenance | H7: 753 | I7: https://www.balisemeteo.com/balise.php?idBalise=5001 | J7: 48.4925 | K7: 7.32306 | L7: Schwartzbach | M7: 3.1 | N7: N·NE·NW | P7: 462 | Q7: 284 | R7: 178 | T7: oui | W7: TMA at 1520m, don't fly higher !_x000D_ Don't fly when sheep are there ! | AA7: http://www.paraglidingearth.com/?site=2943
A8: Alsace | B8: Bas Rhin | C8: 67 | D8: 5002 | E8: J9 | F8: — | G8: OK | H8: 188 | I8: https://www.balisemeteo.com/balise.php?idBalise=5002 | J8: 48.6217 | K8: 7.68361 | L8: Mundolsheim | M8: 1.65 | N8: NW | O8: N·W | P8: 155 | U8: oui | W8: UNDER TMA STRASBOURG_x000D_ MAXIMAL ALTITUDE 150 METERS ABOVE GROUND, ca 300 METERS ABOVE SEA | X8: Wind can become stronger. Don't fly direct above the ridge. _x000D_ Do not train close to the ridge, risks of unwanted take off ! | Y8: Not for beginners. There is always 25-30 kmh wind. You have to be proficient in strong wind reverse takeoffs. | Z8: 15km NW from Strasbourg_x000D_ Colline de Mittelhausbergen | AA8: http://www.paraglidingearth.com/?site=6936 | AB8: Balise associée au site de vol de Mundolsheim. En maintenance (panneau solaire obstrué par végétation)
A9: Alsace | B9: Bas Rhin | C9: 67 | D9: 5095 | E9: Lauf (D) | F9: Holfuy | G9: OK | H9: 800 | I9: https://www.balisemeteo.com/balise.php?idBalise=5095 | J9: 48.62498 | K9: 8.16251 | L9: Sodkopf | M9: 0.03 | N9: W | O9: SW·NW | P9: 775 | Q9: 294 | R9: 481 | T9: oui | AA9: http://www.paraglidingearth.com/?site=8764
A10: Alsace | B10: Bas Rhin | C10: 67 | D10: 3333 | E10: Merkur | F10: Openwindmap | G10: En maintenance | H10: 637 | I10: https://www.balisemeteo.com/balise.php?idBalise=3333 | J10: 48.764437 | K10: 8.280852 | L10: Merkur | M10: 0.11 | N10: NE·SW·W | O10: S | P10: 651 | Q10: 254 | R10: 397 | S10: Landing zone | T10: oui | U10: oui | W10: West: 1. Read the website 2. Inspect LZ before taking the cable car 3. Take the cable car, purchase a "Flieg auf und ab" ticket. This includes the guest site fee for the day. For subsequent flights on the same day, a single "up" ticket is sufficient. Don't use your own car. 4. Ask a local for a briefing. This is mandatory, as we will get in trouble if you crash and we are unable to provide proof that you got a briefing to the police. North East: Boils down to locals only, see website. | X10: See https://www.schwarzwaldgeier.de/wetterstation-merkur/ for the current situation. Local wind is often a good deal stronger than meteo wind. Perfect groundhandling skills are a must. | Y10: Crowded on weekends. XC is usually one-way downwind to the east. | Z10: Cable car or walking. DO NOT drive to the takeoff. The cable car runs from 10 a.m. to 10 p.m. (!) every 5 minutes and is rather low priced. Don't use the vending machine, but the ticket window to grant the lady her commision (no additional cost for you). After purchasing, don't use the tourist queue, but the greenish door to the left. Go to the upper end of the stairs to be out of the way for the tourists leaving the car once it arrives. This means you will be cutting in line. Please make up for that by standing and leaving the seats to the tourists, or, if it's really crowded, skip the first car. The next one will arrive just 5 minutes later. http://www.stadtwerke-baden-baden.de/merkur-bergbahn/ | AA10: http://www.paraglidingearth.com/?site=8662
A11: Alsace | B11: Bas Rhin | C11: 67 | D11: 45 | E11: Reinhardsmunster | F11: Adison | G11: OK | H11: 506 | I11: https://www.balisemeteo.com/balise.php?idBalise=45 | J11: 48.677502 | K11: 7.3119402 | L11: Reinhardsmunster | M11: 0 | N11: NE·E·SE | P11: 526 | Q11: 324 | R11: 202 | T11: oui | U11: oui | W11: Airspace during the weekdays: YOU MUST contact the Phalsbourg airbase (Tél. 03 87 25 21 53) !!! if you are the fist OR last to fly/land!!! see airspace image in the PHOTOS. Do not take off after 30 minutes prior to sunset. In september (ususally the whole month) the site is CLOSED due to the "Brame du Cerf" the annual deer breeding time. Check with the local pilots and/or contact numbers on the Flying site information pannel (on the takeoff and landing). | X11: Take off a very technical, can be dangerous, in strong wind. Magic lift fenomenon on some days in the evening. | Y11: XC to Haut Barr castle (up north) is a classic._x000D_ _x000D_ Max. height : 1520m_x000D_ _x000D_ Flights are NOT ALLOWED from monday 06h00 friday 15h00 (military zone)._x000D_ _x000D_ Access to the site is strictly FORBIDDEN in September (deers fornication ...). | AA11: http://www.paraglidingearth.com/?site=2946
A12: Alsace | B12: Bas Rhin | C12: 67 | D12: 2638 | E12: Rohrbach | F12: Openwindmap | G12: OK | H12: 371 | I12: https://www.balisemeteo.com/balise.php?idBalise=2638 | J12: 49.043964 | K12: 7.251931 | L12: aucun à <5 km
A13: Alsace | B13: Bas Rhin | C13: 67 | D13: 5010 | E13: Strasbourg | F13: — | G13: OK | H13: 144 | I13: https://www.balisemeteo.com/balise.php?idBalise=5010 | J13: 48.575568 | K13: 7.686625 | L13: aucun à <5 km | AB13: Balise située à Strasbourg au sommet de la place des Halles (95m AGL)<br> Bien représentative des conditions possibles<br> Pour le site de Mundolsheim<br> (capteur à ultrtasons)
A14: Alsace | B14: Haut Rhin | C14: 68 | D14: 2829 | E14: ACO Cernay | F14: Openwindmap | G14: OK | H14: 279 | I14: https://www.balisemeteo.com/balise.php?idBalise=2829 | J14: 47.8112 | K14: 7.201219 | L14: aucun à <5 km
A15: Alsace | B15: Haut Rhin | C15: 68 | D15: 5015 | E15: Brezouard | F15: Holfuy | G15: OK | H15: 1188 | I15: https://www.balisemeteo.com/balise.php?idBalise=5015 | J15: 48.1889 | K15: 7.1500001 | L15: Ribeaugoutte | M15: 1.34 | N15: NE | P15: 1050 | W15: http://lavl.free.fr/paragliding-vosges.html_x000D_ http://lavl.free.fr/Espace-Aerien-Vosges.html | AA15: http://www.paraglidingearth.com/?site=2954 | AB15: Cette balise est représentative en direction et force du flux pour les sites suivants : Surcenord, Ribeaugoutte, Bonhomme, Haicot, Fille Morte. Webcam : https://holfuy.com/fr/camera/898
A16: Alsace | B16: Haut Rhin | C16: 68 | D16: 5016 | E16: Gaschney | F16: Openwindmap | G16: OK | H16: 1278 | I16: https://www.balisemeteo.com/balise.php?idBalise=5016 | J16: 48.035022 | K16: 7.0347385 | L16: Le gaschney | M16: 0.07 | N16: S·W | P16: 1258 | Y16: No intermediary landing zone !!!_x000D_ Be careful, landing quite far from take off. | AA16: http://www.paraglidingearth.com/?site=2958 | AB16: Mise en service 06/06/26.
A17: Alsace | B17: Haut Rhin | C17: 68 | D17: 3418 | E17: La Soulce | F17: Openwindmap | G17: OK | H17: 967 | I17: https://www.balisemeteo.com/balise.php?idBalise=3418 | J17: 47.310748 | K17: 7.290744 | L17: Montagne de Moutier | M17: 4.02 | N17: SE | P17: 1080 | T17: oui | Y17: Airspaces in Switzerland are a thought subject. Get all the info you can before flying by visiting http://www.vollibrejura.ch. | AA17: http://www.paraglidingearth.com/?site=7971
A18: Alsace | B18: Haut Rhin | C18: 68 | D18: 5013 | E18: Petit Ballon | F18: — | G18: OK | H18: 1270 | I18: https://www.balisemeteo.com/balise.php?idBalise=5013 | J18: 47.980801 | K18: 7.12567 | L18: aucun à <5 km | AB18: La balise est située au sommet du Petit Ballon à 1272 mètres dégagée de tout obstacle à tous azimuts.
A19: Alsace | B19: Haut Rhin | C19: 68 | D19: 2929 | E19: Schnepfenried | F19: Openwindmap | G19: OK | H19: 1245 | I19: https://www.balisemeteo.com/balise.php?idBalise=2929 | J19: 47.978525 | K19: 7.043083 | L19: Schnepfenried | M19: 0.09 | N19: NE·E | P19: 1221 | Q19: 604 | R19: 617 | T19: oui | U19: oui | X19: Good site the morning until 12h00. | Y19: Restricted Airspace, _x000D_ see http://lavl.free.fr/paragliding-vosges.html | Z19: From road D27 from Munster to road 68 to the | AA19: http://www.paraglidingearth.com/?site=2950 | AB19: Pile neuve Avril 2026
A20: Alsace | B20: Haut Rhin | C20: 68 | D20: 6005 | E20: Tertre Fille Morte | F20: Holfuy | G20: OK | H20: 1050 | I20: https://www.balisemeteo.com/balise.php?idBalise=6005 | J20: 48.2189 | K20: 7.1934 | L20: aucun à <5 km
A21: Alsace | B21: Haut Rhin | C21: 68 | D21: 5085 | E21: Thanner Hubel | F21: — | G21: OK | H21: 1150 | I21: https://www.balisemeteo.com/balise.php?idBalise=5085 | J21: 47.824461 | K21: 7.024826 | L21: aucun à <5 km | AB21: <h2>Mises en garde</h2> <b>Attention</b>, aux indications et aux conditions trompeuses : la balise se situe sur le flanc Est du massif et complètement sous le vent d'Ouest.<br><br> Décollage toléré, non officiel possible, niveau marron conseillé et requis, sur le haut de la chaume, à droite du dernier pylône de la remontée mécanique.<br><br> <b>Attention</b> : accès voiture interdit. Garez-vous au parking (1km plus bas) ou mieux encore, montez à pieds depuis la vallée ou depuis le col du Hundsbruck.<br><br> <b>Attention</b>, les premières prairies atterrissables sont interdites par arrêté municipal et ne sont pas en finesse en l'absence de brise et en présence de vent météo face.
A22: Alsace | B22: Haut Rhin | C22: 68 | D22: 136 | E22: Treh - Markstein | F22: Adison | G22: OK | H22: 1262 | I22: https://www.balisemeteo.com/balise.php?idBalise=136 | J22: 47.926899 | K22: 7.01722 | L22: Treh markstein | M22: 0.42 | N22: SW·W | O22: S·NW | P22: 1227 | Q22: 444 | R22: 783 | T22: oui | U22: oui | W22: http://lavl.free.fr/paragliding-vosges.html :Vosges Airspace Areas_x000D_ or in french with maps : http://lavl.free.fr/Espace-Aerien-Vosges.html | Y22: Be carefull with local airspace rules (airport near) | Z22: Here you can find the official informations and map:_x000D_ http://lavl.free.fr/site-parapente-vosges/SitesValleeThur.html | AA22: http://www.paraglidingearth.com/?site=2959 | AB22: Pas de gonflage ni de pliage sur le dôme (seule la repose au sommet est tolérée). Dégagez la chaumes la voile en boule par le chemin le plus court en rejoignant le sentier de randonnée.
A23: Aquitaine | B23: Dordogne | C23: 24 | D23: 3411 | E23: Aubas | F23: Openwindmap | G23: OK | H23: 200 | I23: https://www.balisemeteo.com/balise.php?idBalise=3411 | J23: 45.08852 | K23: 1.215125 | L23: Aubas | M23: 0.01 | N23: N | O23: NE·NW | P23: 203 | Q23: 80 | R23: 123 | AA23: http://www.paraglidingearth.com/?site=2686
A24: Aquitaine | B24: Dordogne | C24: 24 | D24: 2185 | E24: Coubjours | F24: Openwindmap | G24: En maintenance | H24: 195 | I24: https://www.balisemeteo.com/balise.php?idBalise=2185 | J24: 45.088753 | K24: 1.215725 | L24: Aubas | M24: 0.05 | N24: N | O24: NE·NW | P24: 203 | Q24: 80 | R24: 123 | AA24: http://www.paraglidingearth.com/?site=2686
A25: Aquitaine | B25: Dordogne | C25: 24 | D25: 2828 | E25: Côte de Jor 222m | F25: Openwindmap | G25: OK | H25: 221 | I25: https://www.balisemeteo.com/balise.php?idBalise=2828 | J25: 45.017214 | K25: 1.070796 | L25: St leon sur vezere | M25: 0.02 | N25: SE | P25: 228 | Q25: 228 | AA25: http://www.paraglidingearth.com/?site=2685
A26: Aquitaine | B26: Dordogne | C26: 24 | D26: 2143 | E26: St Léon sur Vézère | F26: Openwindmap | G26: En maintenance | H26: 221 | I26: https://www.balisemeteo.com/balise.php?idBalise=2143 | J26: 45.017288 | K26: 1.070672 | L26: St leon sur vezere | M26: 0.01 | N26: SE | P26: 228 | Q26: 228 | AA26: http://www.paraglidingearth.com/?site=2685
A27: Aquitaine | B27: Gironde | C27: 33 | D27: 2415 | E27: Plages du Crohot et du Porge | F27: Openwindmap | G27: En maintenance | H27: 18 | I27: https://www.balisemeteo.com/balise.php?idBalise=2415 | J27: 44.841316 | K27: -1.225446 | L27: aucun à <5 km | AB27: Pioupiou placé en haut de la dune entre les plages du Crohot et du Porge.
A28: Aquitaine | B28: Gironde | C28: 33 | D28: 64 | E28: Pyla Pilat | F28: Adison | G28: OK | H28: 55 | I28: https://www.balisemeteo.com/balise.php?idBalise=64 | J28: 44.576111 | K28: -1.2247222 | L28: Dune de Pilat | M28: 0.45 | N28: W·NW | P28: 50 | T28: oui | U28: oui | W28: It's very busy in Summer but so fun all the Time | Y28: The Fisrt International Competition of Paragliding directly in the Sand !_x000D_ http://www.wagas-festival.com/_x000D_ or here http://www.parateam.com/_x000D_ You have an smashing video here from 'the king of the dune's' :_x000D_ http://pyal.ifrance.com/cariboost1/ | AA28: http://www.paraglidingearth.com/?site=7217 | AB28: PIÉTINEMENT des OYATS INTERDIT (protection dunaire). Casque et accélérateur obligatoires (risque de reculade au-delà de 25 Km/h). VOL à "La Corniche" (Nord Dune) INTERDIT du 1/04 au 15/11 (Arrêté municipal).
A29: Aquitaine | B29: Lot et Garonne | C29: 47 | D29: 165 | E29: Pech de Berre | F29: Adison | G29: OK | H29: 107 | I29: https://www.balisemeteo.com/balise.php?idBalise=165 | J29: 44.3242 | K29: 0.34916699 | L29: Nicole | M29: 0.18 | N29: NE·SW | O29: E·W | P29: 149 | Q29: 32 | R29: 117 | T29: oui | U29: oui | Y29: Be careful in the air not to fly into the cross. | AA29: http://www.paraglidingearth.com/?site=2838
A30: Aquitaine | B30: Lot et Garonne | C30: 47 | D30: 2906 | E30: Penne d'Agenais | F30: Openwindmap | G30: OK | H30: 219 | I30: https://www.balisemeteo.com/balise.php?idBalise=2906 | J30: 44.390455 | K30: 0.823063 | L30: Penne d\'agenais | M30: 0.09 | N30: N·NW | O30: NE | P30: 197 | Q30: 58 | R30: 139 | T30: oui | U30: oui | Z30: To get there, follow the signs for 'penne d'a' untill you reach the top of the road, park at the entrance of the village. | AA30: http://www.paraglidingearth.com/?site=2836 | AB30: Recommandations : Orientations favorables du vent : Nord-ouest à Nord. Décollage idéal : face voile puis monter sur la butte avant le décollage. (Ne pas monter au sommet de la butte) Le décollage est favorisé par l’arrivée d’un thermique modéré. Conseil : Découvrir le site avec un adhérent du club. A éviter : -décollage sans vent (mini : 10 km/h) -Décollage par vents forts (>25km/h) -Directions du vent en dehors des orientations favorables Danger : effet venturi possible entre le terrain de décollage et la basilique (au dessus du village). Terrain d’atterrissage : attention à la ligne de chemin de fer au sud du terrain, présence d’une ligne électrique. Ne pas survoler la maison à l’est du terrain, risque de gradient à l’arrivée qui augmente le taux de chute.
A31: Aquitaine | B31: Pyrénées Atlantiques | C31: 64 | D31: 138 | E31: Accous | F31: Adison | G31: OK | H31: 1590 | I31: https://www.balisemeteo.com/balise.php?idBalise=138 | J31: 43.024399 | K31: -0.65444398 | L31: Le Layens | M31: 0.91 | N31: S | P31: 1518 | AA31: http://www.paraglidingearth.com/?site=2921 | AB31: La balise du Layens est dégagé de tous reliefs, et, est sous l'influence du vent météo. Le versant sud peut donner des vitesses de brises de pente faibles lors de vent météo nul.
A32: Aquitaine | B32: Pyrénées Atlantiques | C32: 64 | D32: 43 | E32: Baigura | F32: Openwindmap | G32: OK | H32: 838 | I32: https://www.balisemeteo.com/balise.php?idBalise=43 | J32: 43.294601 | K32: -1.28878 | L32: Baigura | M32: 0.28 | N32: N·NE·E·W·NW | P32: 830 | Q32: 310 | R32: 520 | AA32: http://www.paraglidingearth.com/?site=2918
A33: Aquitaine | B33: Pyrénées Atlantiques | C33: 64 | D33: 183 | E33: Issarbe | F33: Adison | G33: OK | H33: 1435 | I33: https://www.balisemeteo.com/balise.php?idBalise=183 | J33: 43.020599 | K33: -0.79958498 | L33: Issarbe | M33: 0.25 | P33: 1416 | Z33: Easy Access - drive up to the cross-country ski station - there is a building and parking opposite - the take off is just after the building and has windsocks and cleared area. | AA33: http://www.paraglidingearth.com/?site=21666 | AB33: Vu son emplacement voulu à proximité du décollage, au dessus de 40-50km/h, l'orientation de la direction peut être faussée par des "rouleaux" de vent météo (principalement par vent de sud).
A34: Aquitaine | B34: Pyrénées Atlantiques | C34: 64 | D34: 2336 | E34: La Rhune | F34: Openwindmap | G34: OK | H34: 864 | I34: https://www.balisemeteo.com/balise.php?idBalise=2336 | J34: 43.308456 | K34: -1.632848 | L34: aucun à <5 km | AB34: Informations non fiables remontées en date du 28/1/2020 Maintenance
A35: Auvergne | B35: Allier | C35: 03 | D35: 3520 | E35: Champbenest | F35: Openwindmap | G35: OK | H35: 352 | I35: https://www.balisemeteo.com/balise.php?idBalise=3520 | J35: 46.380127 | K35: 2.633713 | L35: aucun à <5 km
A36: Auvergne | B36: Allier | C36: 03 | D36: 5105 | E36: LE VERNET | F36: Openwindmap | G36: OK | H36: 428 | I36: https://www.balisemeteo.com/balise.php?idBalise=5105 | J36: 46.1022 | K36: 3.4556 | L36: aucun à <5 km
A37: Auvergne | B37: Allier | C37: 03 | D37: 5014 | E37: Loge des Gardes | F37: Holfuy | G37: OK | H37: 1101 | I37: https://www.balisemeteo.com/balise.php?idBalise=5014 | J37: 46.0047 | K37: 3.7942801 | L37: Laprugne Vol Libre | M37: 0.03 | P37: 1101 | AA37: http://www.paraglidingearth.com/?site=22046 | AB37: Décollage facile pas de rupture de pente. Atterrissage officiel un peu loin mais atterro "secours" a mi-distance. Site en Ouest idéalement ONO.
A38: Auvergne | B38: Cantal | C38: 15 | D38: 3613 | E38: Brezons | F38: Openwindmap | G38: OK | H38: 1242 | I38: https://www.balisemeteo.com/balise.php?idBalise=3613 | J38: 45.007131 | K38: 2.812402 | L38: Brezons | M38: 0.16 | N38: SW·W | O38: S·NW | P38: 1293 | Q38: 847 | R38: 446 | T38: oui | X38: Very strong thermals in summer._x000D_ _x000D_ Do not land above the cliff to the left of taking off. Dangerous. | Y38: Super thermical site. Cross possible without risks._x000D_ Very cool lift on evenings | Z38: Stop at the FFVL board on the side of the road coming from pratdebouc._x000D_ The take off is at the end of the trak, trough the fields._x000D_ _x000D_ Beware of the cows. | AA38: http://www.paraglidingearth.com/?site=2635
A39: Auvergne | B39: Cantal | C39: 15 | D39: 2571 | E39: Embec | F39: Openwindmap | G39: OK | H39: 1434 | I39: https://www.balisemeteo.com/balise.php?idBalise=2571 | J39: 45.161346 | K39: 2.771724 | L39: Dienne - pierre de labro | M39: 2.03 | N39: SE·S | P39: 1301 | AA39: http://www.paraglidingearth.com/?site=2633 | AB39: Site en E, SE ; turbulent en SO
A40: Auvergne | B40: Cantal | C40: 15 | D40: 2570 | E40: Engolneuf | F40: Openwindmap | G40: OK | H40: 1462 | I40: https://www.balisemeteo.com/balise.php?idBalise=2570 | J40: 45.132385 | K40: 2.789699 | L40: Col de serre | M40: 0.15 | N40: NW | P40: 1436 | AA40: http://www.paraglidingearth.com/?site=2632 | AB40: Site SO ; turbulent en SE
...

Sheet Synthèse
A1: Synthèse par région
A3: Région | B3: Nb balises | C3: Avec spot <5 km
A4: Alsace | B4: =COUNTIF(Balises!A:A,A4) -> 21 | C4: =COUNTIFS(Balises!A:A,A4,Balises!L:L,"<>aucun à <5 km") -> 12
A5: Aquitaine | B5: =COUNTIF(Balises!A:A,A5) -> 12 | C5: =COUNTIFS(Balises!A:A,A5,Balises!L:L,"<>aucun à <5 km") -> 10
A6: Auvergne | B6: =COUNTIF(Balises!A:A,A6) -> 28 | C6: =COUNTIFS(Balises!A:A,A6,Balises!L:L,"<>aucun à <5 km") -> 26
A7: Basse Normandie | B7: =COUNTIF(Balises!A:A,A7) -> 14 | C7: =COUNTIFS(Balises!A:A,A7,Balises!L:L,"<>aucun à <5 km") -> 13
A8: Bourgogne | B8: =COUNTIF(Balises!A:A,A8) -> 30 | C8: =COUNTIFS(Balises!A:A,A8,Balises!L:L,"<>aucun à <5 km") -> 24
A9: Bretagne | B9: =COUNTIF(Balises!A:A,A9) -> 15 | C9: =COUNTIFS(Balises!A:A,A9,Balises!L:L,"<>aucun à <5 km") -> 14
A10: Centre | B10: =COUNTIF(Balises!A:A,A10) -> 1 | C10: =COUNTIFS(Balises!A:A,A10,Balises!L:L,"<>aucun à <5 km") -> 0
A11: Champagne-Ardenne | B11: =COUNTIF(Balises!A:A,A11) -> 18 | C11: =COUNTIFS(Balises!A:A,A11,Balises!L:L,"<>aucun à <5 km") -> 15
A12: Corse | B12: =COUNTIF(Balises!A:A,A12) -> 9 | C12: =COUNTIFS(Balises!A:A,A12,Balises!L:L,"<>aucun à <5 km") -> 7
A13: Franche-Comté | B13: =COUNTIF(Balises!A:A,A13) -> 37 | C13: =COUNTIFS(Balises!A:A,A13,Balises!L:L,"<>aucun à <5 km") -> 32
A14: Haute Normandie | B14: =COUNTIF(Balises!A:A,A14) -> 12 | C14: =COUNTIFS(Balises!A:A,A14,Balises!L:L,"<>aucun à <5 km") -> 11
A15: Ile de France | B15: =COUNTIF(Balises!A:A,A15) -> 3 | C15: =COUNTIFS(Balises!A:A,A15,Balises!L:L,"<>aucun à <5 km") -> 1
... A26: Outre Mer | B26: =COUNTIF(Balises!A:A,A26) -> 10 | C26: =COUNTIFS(Balises!A:A,A26,Balises!L:L,"<>aucun à <5 km") -> 7
A27: TOTAL | B27: =SUM(B4:B26) -> 634 | C27: =SUM(C4:C26) -> 516
A29: Source : balisemeteo.com (relevé du 15/07/2026) croisé avec Paragliding Earth (site de vol le plus proche dans un rayon de 5 km — données contributives, à recouper avec les fiches FFVL avant de voler).
